<?xml version="1.0" encoding="UTF-8"?>
<testng-results skipped="0" failed="4" total="6" passed="2">
  <reporter-output>
  </reporter-output>
  <suite name="Ethoca_Challenge" duration-ms="85540" started-at="2019-01-05T03:30:14Z" finished-at="2019-01-05T03:31:40Z">
    <groups>
    </groups>
    <test name="MagicMouse_Purchase" duration-ms="35663" started-at="2019-01-05T03:30:14Z" finished-at="2019-01-05T03:30:50Z">
      <class name="exercise.Test01">
        <test-method status="PASS" signature="iniTest()[pri:0, instance:exercise.Test01@17550481]" name="iniTest" is-config="true" duration-ms="3638" started-at="2019-01-04T22:30:14Z" finished-at="2019-01-04T22:30:18Z">
          <reporter-output>
          </reporter-output>
        </test-method> <!-- iniTest -->
        <test-method status="FAIL" signature="TestCase01()[pri:0, instance:exercise.Test01@17550481]" name="TestCase01" duration-ms="31305" started-at="2019-01-04T22:30:18Z" finished-at="2019-01-04T22:30:49Z">
          <exception class="java.lang.AssertionError">
            <message>
              <![CDATA[Error has occured during Validating product]]>
            </message>
            <full-stacktrace>
              <![CDATA[java.lang.AssertionError: Error has occured during Validating product
	at org.testng.Assert.fail(Assert.java:94)
	at businessComponents.BusinessComponents.validateProductSelect(BusinessComponents.java:90)
	at exercise.Test01.TestCase01(Test01.java:27)
	at sun.reflect.NativeMethodAccessorImpl.invoke0(Native Method)
	at sun.reflect.NativeMethodAccessorImpl.invoke(NativeMethodAccessorImpl.java:62)
	at sun.reflect.DelegatingMethodAccessorImpl.invoke(DelegatingMethodAccessorImpl.java:43)
	at java.lang.reflect.Method.invoke(Method.java:498)
	at org.testng.internal.MethodInvocationHelper.invokeMethod(MethodInvocationHelper.java:85)
	at org.testng.internal.Invoker.invokeMethod(Invoker.java:639)
	at org.testng.internal.Invoker.invokeTestMethod(Invoker.java:816)
	at org.testng.internal.Invoker.invokeTestMethods(Invoker.java:1124)
	at org.testng.internal.TestMethodWorker.invokeTestMethods(TestMethodWorker.java:125)
	at org.testng.internal.TestMethodWorker.run(TestMethodWorker.java:108)
	at org.testng.TestRunner.privateRun(TestRunner.java:774)
	at org.testng.TestRunner.run(TestRunner.java:624)
	at org.testng.SuiteRunner.runTest(SuiteRunner.java:359)
	at org.testng.SuiteRunner.runSequentially(SuiteRunner.java:354)
	at org.testng.SuiteRunner.privateRun(SuiteRunner.java:312)
	at org.testng.SuiteRunner.run(SuiteRunner.java:261)
	at org.testng.SuiteRunnerWorker.runSuite(SuiteRunnerWorker.java:52)
	at org.testng.SuiteRunnerWorker.run(SuiteRunnerWorker.java:86)
	at org.testng.TestNG.runSuitesSequentially(TestNG.java:1191)
	at org.testng.TestNG.runSuitesLocally(TestNG.java:1116)
	at org.testng.TestNG.run(TestNG.java:1024)
	at org.apache.maven.surefire.testng.TestNGExecutor.run(TestNGExecutor.java:281)
	at org.apache.maven.surefire.testng.TestNGXmlTestSuite.execute(TestNGXmlTestSuite.java:75)
	at org.apache.maven.surefire.testng.TestNGProvider.invoke(TestNGProvider.java:121)
	at org.apache.maven.surefire.booter.ForkedBooter.invokeProviderInSameClassLoader(ForkedBooter.java:290)
	at org.apache.maven.surefire.booter.ForkedBooter.runSuitesInProcess(ForkedBooter.java:242)
	at org.apache.maven.surefire.booter.ForkedBooter.main(ForkedBooter.java:121)
]]>
            </full-stacktrace>
          </exception> <!-- java.lang.AssertionError -->
          <reporter-output>
          </reporter-output>
        </test-method> <!-- TestCase01 -->
        <test-method status="PASS" signature="cleanUp()[pri:0, instance:exercise.Test01@17550481]" name="cleanUp" is-config="true" duration-ms="685" started-at="2019-01-04T22:30:49Z" finished-at="2019-01-04T22:30:50Z">
          <reporter-output>
          </reporter-output>
        </test-method> <!-- cleanUp -->
      </class> <!-- exercise.Test01 -->
    </test> <!-- MagicMouse_Purchase -->
    <test name="AppleTV_Purchase" duration-ms="49835" started-at="2019-01-05T03:30:50Z" finished-at="2019-01-05T03:31:40Z">
      <class name="exercise.Test02">
        <test-method status="PASS" signature="iniTest()[pri:0, instance:exercise.Test02@6b143ee9]" name="iniTest" is-config="true" duration-ms="2291" started-at="2019-01-04T22:30:50Z" finished-at="2019-01-04T22:30:52Z">
          <reporter-output>
          </reporter-output>
        </test-method> <!-- iniTest -->
        <test-method status="PASS" signature="login()[pri:1, instance:exercise.Test02@6b143ee9]" name="login" duration-ms="3456" started-at="2019-01-04T22:30:52Z" finished-at="2019-01-04T22:30:55Z">
          <reporter-output>
          </reporter-output>
        </test-method> <!-- login -->
        <test-method status="PASS" signature="SelectItem()[pri:2, instance:exercise.Test02@6b143ee9]" name="SelectItem" duration-ms="3217" started-at="2019-01-04T22:30:55Z" finished-at="2019-01-04T22:30:59Z">
          <reporter-output>
          </reporter-output>
        </test-method> <!-- SelectItem -->
        <test-method status="FAIL" signature="validateProduct_Select()[pri:3, instance:exercise.Test02@6b143ee9]" name="validateProduct_Select" duration-ms="20082" started-at="2019-01-04T22:30:59Z" finished-at="2019-01-04T22:31:19Z">
          <exception class="java.lang.AssertionError">
            <message>
              <![CDATA[Error has occured during Validating product]]>
            </message>
            <full-stacktrace>
              <![CDATA[java.lang.AssertionError: Error has occured during Validating product
	at org.testng.Assert.fail(Assert.java:94)
	at businessComponents.BusinessComponents.validateProductSelect(BusinessComponents.java:90)
	at exercise.Test02.validateProduct_Select(Test02.java:35)
	at sun.reflect.NativeMethodAccessorImpl.invoke0(Native Method)
	at sun.reflect.NativeMethodAccessorImpl.invoke(NativeMethodAccessorImpl.java:62)
	at sun.reflect.DelegatingMethodAccessorImpl.invoke(DelegatingMethodAccessorImpl.java:43)
	at java.lang.reflect.Method.invoke(Method.java:498)
	at org.testng.internal.MethodInvocationHelper.invokeMethod(MethodInvocationHelper.java:85)
	at org.testng.internal.Invoker.invokeMethod(Invoker.java:639)
	at org.testng.internal.Invoker.invokeTestMethod(Invoker.java:816)
	at org.testng.internal.Invoker.invokeTestMethods(Invoker.java:1124)
	at org.testng.internal.TestMethodWorker.invokeTestMethods(TestMethodWorker.java:125)
	at org.testng.internal.TestMethodWorker.run(TestMethodWorker.java:108)
	at org.testng.TestRunner.privateRun(TestRunner.java:774)
	at org.testng.TestRunner.run(TestRunner.java:624)
	at org.testng.SuiteRunner.runTest(SuiteRunner.java:359)
	at org.testng.SuiteRunner.runSequentially(SuiteRunner.java:354)
	at org.testng.SuiteRunner.privateRun(SuiteRunner.java:312)
	at org.testng.SuiteRunner.run(SuiteRunner.java:261)
	at org.testng.SuiteRunnerWorker.runSuite(SuiteRunnerWorker.java:52)
	at org.testng.SuiteRunnerWorker.run(SuiteRunnerWorker.java:86)
	at org.testng.TestNG.runSuitesSequentially(TestNG.java:1191)
	at org.testng.TestNG.runSuitesLocally(TestNG.java:1116)
	at org.testng.TestNG.run(TestNG.java:1024)
	at org.apache.maven.surefire.testng.TestNGExecutor.run(TestNGExecutor.java:281)
	at org.apache.maven.surefire.testng.TestNGXmlTestSuite.execute(TestNGXmlTestSuite.java:75)
	at org.apache.maven.surefire.testng.TestNGProvider.invoke(TestNGProvider.java:121)
	at org.apache.maven.surefire.booter.ForkedBooter.invokeProviderInSameClassLoader(ForkedBooter.java:290)
	at org.apache.maven.surefire.booter.ForkedBooter.runSuitesInProcess(ForkedBooter.java:242)
	at org.apache.maven.surefire.booter.ForkedBooter.main(ForkedBooter.java:121)
]]>
            </full-stacktrace>
          </exception> <!-- java.lang.AssertionError -->
          <reporter-output>
          </reporter-output>
        </test-method> <!-- validateProduct_Select -->
        <test-method status="FAIL" signature="enterUserDetails()[pri:4, instance:exercise.Test02@6b143ee9]" name="enterUserDetails" duration-ms="20027" started-at="2019-01-04T22:31:19Z" finished-at="2019-01-04T22:31:39Z">
          <exception class="java.lang.AssertionError">
            <message>
              <![CDATA[Error has occured during User entry details page]]>
            </message>
            <full-stacktrace>
              <![CDATA[java.lang.AssertionError: Error has occured during User entry details page
	at org.testng.Assert.fail(Assert.java:94)
	at businessComponents.BusinessComponents.enterUserDetails(BusinessComponents.java:106)
	at exercise.Test02.enterUserDetails(Test02.java:40)
	at sun.reflect.NativeMethodAccessorImpl.invoke0(Native Method)
	at sun.reflect.NativeMethodAccessorImpl.invoke(NativeMethodAccessorImpl.java:62)
	at sun.reflect.DelegatingMethodAccessorImpl.invoke(DelegatingMethodAccessorImpl.java:43)
	at java.lang.reflect.Method.invoke(Method.java:498)
	at org.testng.internal.MethodInvocationHelper.invokeMethod(MethodInvocationHelper.java:85)
	at org.testng.internal.Invoker.invokeMethod(Invoker.java:639)
	at org.testng.internal.Invoker.invokeTestMethod(Invoker.java:816)
	at org.testng.internal.Invoker.invokeTestMethods(Invoker.java:1124)
	at org.testng.internal.TestMethodWorker.invokeTestMethods(TestMethodWorker.java:125)
	at org.testng.internal.TestMethodWorker.run(TestMethodWorker.java:108)
	at org.testng.TestRunner.privateRun(TestRunner.java:774)
	at org.testng.TestRunner.run(TestRunner.java:624)
	at org.testng.SuiteRunner.runTest(SuiteRunner.java:359)
	at org.testng.SuiteRunner.runSequentially(SuiteRunner.java:354)
	at org.testng.SuiteRunner.privateRun(SuiteRunner.java:312)
	at org.testng.SuiteRunner.run(SuiteRunner.java:261)
	at org.testng.SuiteRunnerWorker.runSuite(SuiteRunnerWorker.java:52)
	at org.testng.SuiteRunnerWorker.run(SuiteRunnerWorker.java:86)
	at org.testng.TestNG.runSuitesSequentially(TestNG.java:1191)
	at org.testng.TestNG.runSuitesLocally(TestNG.java:1116)
	at org.testng.TestNG.run(TestNG.java:1024)
	at org.apache.maven.surefire.testng.TestNGExecutor.run(TestNGExecutor.java:281)
	at org.apache.maven.surefire.testng.TestNGXmlTestSuite.execute(TestNGXmlTestSuite.java:75)
	at org.apache.maven.surefire.testng.TestNGProvider.invoke(TestNGProvider.java:121)
	at org.apache.maven.surefire.booter.ForkedBooter.invokeProviderInSameClassLoader(ForkedBooter.java:290)
	at org.apache.maven.surefire.booter.ForkedBooter.runSuitesInProcess(ForkedBooter.java:242)
	at org.apache.maven.surefire.booter.ForkedBooter.main(ForkedBooter.java:121)
]]>
            </full-stacktrace>
          </exception> <!-- java.lang.AssertionError -->
          <reporter-output>
          </reporter-output>
        </test-method> <!-- enterUserDetails -->
        <test-method status="FAIL" signature="validateTranPage()[pri:5, instance:exercise.Test02@6b143ee9]" name="validateTranPage" duration-ms="105" started-at="2019-01-04T22:31:39Z" finished-at="2019-01-04T22:31:39Z">
          <exception class="java.lang.AssertionError">
            <message>
              <![CDATA[Transaction page NOT displayed expected [true] but found [false]]]>
            </message>
            <full-stacktrace>
              <![CDATA[java.lang.AssertionError: Transaction page NOT displayed expected [true] but found [false]
	at org.testng.Assert.fail(Assert.java:94)
	at org.testng.Assert.failNotEquals(Assert.java:496)
	at org.testng.Assert.assertTrue(Assert.java:42)
	at businessComponents.BusinessComponents.validateTranPage(BusinessComponents.java:117)
	at exercise.Test02.validateTranPage(Test02.java:45)
	at sun.reflect.NativeMethodAccessorImpl.invoke0(Native Method)
	at sun.reflect.NativeMethodAccessorImpl.invoke(NativeMethodAccessorImpl.java:62)
	at sun.reflect.DelegatingMethodAccessorImpl.invoke(DelegatingMethodAccessorImpl.java:43)
	at java.lang.reflect.Method.invoke(Method.java:498)
	at org.testng.internal.MethodInvocationHelper.invokeMethod(MethodInvocationHelper.java:85)
	at org.testng.internal.Invoker.invokeMethod(Invoker.java:639)
	at org.testng.internal.Invoker.invokeTestMethod(Invoker.java:816)
	at org.testng.internal.Invoker.invokeTestMethods(Invoker.java:1124)
	at org.testng.internal.TestMethodWorker.invokeTestMethods(TestMethodWorker.java:125)
	at org.testng.internal.TestMethodWorker.run(TestMethodWorker.java:108)
	at org.testng.TestRunner.privateRun(TestRunner.java:774)
	at org.testng.TestRunner.run(TestRunner.java:624)
	at org.testng.SuiteRunner.runTest(SuiteRunner.java:359)
	at org.testng.SuiteRunner.runSequentially(SuiteRunner.java:354)
	at org.testng.SuiteRunner.privateRun(SuiteRunner.java:312)
	at org.testng.SuiteRunner.run(SuiteRunner.java:261)
	at org.testng.SuiteRunnerWorker.runSuite(SuiteRunnerWorker.java:52)
	at org.testng.SuiteRunnerWorker.run(SuiteRunnerWorker.java:86)
	at org.testng.TestNG.runSuitesSequentially(TestNG.java:1191)
	at org.testng.TestNG.runSuitesLocally(TestNG.java:1116)
	at org.testng.TestNG.run(TestNG.java:1024)
	at org.apache.maven.surefire.testng.TestNGExecutor.run(TestNGExecutor.java:281)
	at org.apache.maven.surefire.testng.TestNGXmlTestSuite.execute(TestNGXmlTestSuite.java:75)
	at org.apache.maven.surefire.testng.TestNGProvider.invoke(TestNGProvider.java:121)
	at org.apache.maven.surefire.booter.ForkedBooter.invokeProviderInSameClassLoader(ForkedBooter.java:290)
	at org.apache.maven.surefire.booter.ForkedBooter.runSuitesInProcess(ForkedBooter.java:242)
	at org.apache.maven.surefire.booter.ForkedBooter.main(ForkedBooter.java:121)
]]>
            </full-stacktrace>
          </exception> <!-- java.lang.AssertionError -->
          <reporter-output>
          </reporter-output>
        </test-method> <!-- validateTranPage -->
        <test-method status="PASS" signature="cleanUp()[pri:0, instance:exercise.Test02@6b143ee9]" name="cleanUp" is-config="true" duration-ms="648" started-at="2019-01-04T22:31:39Z" finished-at="2019-01-04T22:31:40Z">
          <reporter-output>
          </reporter-output>
        </test-method> <!-- cleanUp -->
      </class> <!-- exercise.Test02 -->
    </test> <!-- AppleTV_Purchase -->
  </suite> <!-- Ethoca_Challenge -->
</testng-results>
